<?xml version="1.0" encoding="utf-8"?>
<robot
  name="stray">
  <link
    name="base">
    
    <visual>
      <origin
        xyz="0 0 0"
        rpy="-1.57 0 0" />
      <geometry>
        <mesh
          filename="../meshes_dae/base.dae" scale="1.0 1.0 1.0" />
        <!-- <box size="0.01 0.01 0.01"/> -->
      </geometry>
      <material
        name="">
        <color
          rgba="0.75294 0.75294 0.75294 1" />
      </material>
    </visual>
    <collision>
      <origin
        xyz="0.0 0 0.025"
        rpy="0 0 0" />
      <geometry>
        <!-- <mesh
          filename="../meshes_dae/base.dae" scale="1.0 1.0 1.0" /> -->
        <box size="0.1 0.08 0.125"/>
      </geometry>
    </collision>
  </link>
  <!-- Fixed joint to add dummy inertia link -->
  <joint name="base_to_base_inertia" type="fixed">
    <parent link="base"/>
    <child link="base_inertia"/>
    <origin rpy="0 0 0" xyz="0 0 0"/>
  </joint>
  <!-- Dummy inertia link, because KDL cannot have inertia on the base link -->
  <link name="base_inertia">
    <inertial>
      <origin
        xyz="0.0042084 0.00046194 -0.0029435"
        rpy="0 0 0" />
      <mass
        value="3.274891" />
      <inertia
        ixx="0.011369"
        ixy="0.000061"
        ixz="-0.000121"
        iyy="0.012224"
        iyz="-0.000072"
        izz="0.018636" />
    </inertial>
  </link>
  <link
    name="LF_hip">
    <inertial>
      <origin
        xyz="-0.0033566 0.00035428 -9.8499E-05"
        rpy="0 0 0" />
      <mass
        value="0.605136" />
      <inertia
        ixx="0.000376"
        ixy="-0.000003"
        ixz="0.000000"
        iyy="0.000726"
        iyz="-0.000001"
        izz="0.000446" />
    </inertial>
    <visual>
      <origin
        xyz="0 0 0"
        rpy="-1.57 0 0" />
      <geometry>
        <mesh
          filename="../meshes_dae/LF_hip.dae" scale="1.0 1.0 1.0" />
      </geometry>
      <material
        name="">
        <color
          rgba="0.752941176470588 0.752941176470588 0.752941176470588 1" />
      </material>
    </visual>
    <collision>
      <origin
        xyz="0 0 0"
        rpy="0 0 0" />
      <geometry>
        <mesh
          filename="../meshes_dae/LF_hip.dae" scale="1.0 1.0 1.0" />
        <!-- <box size="0.01 0.01 0.01"/> -->
      </geometry>
    </collision>
  </link>
  <joint
    name="LF_HAA"
    type="revolute">
    <origin
      xyz="0.13205 0.06 0"
      rpy="0 0 0" />
    <parent
      link="base" />
    <child
      link="LF_hip" />
    <axis
      xyz="1 0 0" />
    <limit
      lower="-1"
      upper="1"
      effort="20"
      velocity="45" />
  </joint>
  <link
    name="LF_thigh">
    <inertial>
      <origin
        xyz="-0.0035577 -0.016764 -0.030534"
        rpy="0 0 0" />
      <mass
        value="1.178539" />
      <inertia
        ixx="0.005883"
        ixy="0.000078"
        ixz="-0.000384"
        iyy="0.006054"
        iyz="0.000631"
        izz="0.001155" />
    </inertial>
    <visual>
      <origin
        xyz="0 0 0"
        rpy="-1.57 0 0" />
      <geometry>
        <mesh
          filename="../meshes_dae/LF_thigh.dae" scale="1.0 1.0 1.0" />
      </geometry>
      <material
        name="">
        <color
          rgba="0.752941176470588 0.752941176470588 0.752941176470588 1" />
      </material>
    </visual>
    <collision>
      <origin
        xyz="0 0 0"
        rpy="0 0 0" />
      <geometry>
        <mesh
          filename="../meshes_dae/LF_thigh.dae" scale="1.0 1.0 1.0" />
        <!-- <box size="0.01 0.01 0.01"/> -->
      </geometry>
    </collision>
  </link>
  <joint
    name="LF_HFE"
    type="revolute">
    <origin
      xyz="0 0.077 0"
      rpy="0 0 0" />
    <parent
      link="LF_hip" />
    <child
      link="LF_thigh" />
    <axis
      xyz="0 1 0" />
    <limit
      lower="0"
      upper="1.57"
      effort="20"
      velocity="45" />
  </joint>
  <link
    name="LF_calf">
    <inertial>
      <origin
        xyz="0.0032267 0.0018108 -0.10497"
        rpy="0 0 0" />
      <mass
        value="0.251969" />
      <inertia
        ixx="0.002086"
        ixy="0.000000"
        ixz="0.000002"
        iyy="0.002097"
        iyz="0.000045"
        izz="0.000036" />
    </inertial>
    <visual>
      <origin
        xyz="0 0 0"
        rpy="-1.57 0 0" />
      <geometry>
        <mesh
          filename="../meshes_dae/LF_calf.dae" scale="1.0 1.0 1.0" />
      </geometry>
      <material
        name="">
        <color
          rgba="0.752941176470588 0.752941176470588 0.752941176470588 1" />
      </material>
    </visual>
    <collision>
      <origin
        xyz="0 0 0"
        rpy="0 0 0" />
      <geometry>
        <mesh
          filename="../meshes_dae/LF_calf.dae" scale="1.0 1.0 1.0" />
      </geometry>
    </collision>
  </link>
  <joint
    name="LF_KFE"
    type="revolute">
    <origin
      xyz="0 0 -0.21"
      rpy="0 0 0" />
    <parent
      link="LF_thigh" />
    <child
      link="LF_calf" />
    <axis
      xyz="0 1 0" />
    <limit
      lower="-2.7"
      upper="-1.14"
      effort="20"
      velocity="45" />
  </joint>
  <link
    name="LF_FOOT">
    <inertial>
      <origin
        xyz="0.0019997 0.0051994 0.007454"
        rpy="0 0 0" />
      <mass
        value="0.089225" />
      <inertia
        ixx="0.000027"
        ixy="0.000000"
        ixz="-0.000003"
        iyy="0.000027"
        iyz="-0.000001"
        izz="0.000015" />
    </inertial>
    <visual>
      <origin
        xyz="0 0 0"
        rpy="-1.57 0 0" />
      <geometry>
        <mesh
          filename="../meshes_dae/LF_FOOT.dae" scale="1.0 1.0 1.0" />
      </geometry>
      <material
        name="">
        <color
          rgba="0.486274509803922 0.486274509803922 0.486274509803922 1" />
      </material>
    </visual>
    <collision>
      <origin
        xyz="0 0 0"
        rpy="0 0 0" />
      <geometry>
        <!-- <mesh
          filename="../meshes_dae/LF_FOOT.dae" scale="1.0 1.0 1.0" /> -->
        <sphere radius="0.02"/>
      </geometry>
    </collision>
  </link>
  <joint
    name="LF_foot_fixed"
    type="fixed">
    <origin
      xyz="0 0 -0.21"
      rpy="0 0 0" />
    <parent
      link="LF_calf" />
    <child
      link="LF_FOOT" />
    <axis
      xyz="0 0 0" />
  </joint>
  <link
    name="RF_hip">
    <inertial>
      <origin
        xyz="-0.0033566 -0.00035428 9.8499E-05"
        rpy="0 0 0" />
      <mass
        value="0.605136" />
      <inertia
        ixx="0.000376"
        ixy="0.000003"
        ixz="0.000000"
        iyy="0.000726"
        iyz="-0.000001"
        izz="0.000446" />
    </inertial>
    <visual>
      <origin
        xyz="0 0 0"
        rpy="-1.57 0 0" />
      <geometry>
        <mesh
          filename="../meshes_dae/RF_hip.dae" scale="1.0 1.0 1.0" />
      </geometry>
      <material
        name="">
        <color
          rgba="0.752941176470588 0.752941176470588 0.752941176470588 1" />
      </material>
    </visual>
    <collision>
      <origin
        xyz="0 0 0"
        rpy="0 0 0" />
      <geometry>
        <mesh
          filename="../meshes_dae/RF_hip.dae" scale="1.0 1.0 1.0" />
        <!-- <box size="0.01 0.01 0.01"/> -->
      </geometry>
    </collision>
  </link>
  <joint
    name="RF_HAA"
    type="revolute">
    <origin
      xyz="0.13205 -0.06 0"
      rpy="0 0 0" />
    <parent
      link="base" />
    <child
      link="RF_hip" />
    <axis
      xyz="1 0 0" />
    <limit
      lower="-1"
      upper="1"
      effort="20"
      velocity="45" />
  </joint>
  <link
    name="RF_thigh">
    <inertial>
      <origin
        xyz="-0.0035577 0.016764 -0.030534"
        rpy="0 0 0" />
      <mass
        value="1.178539" />
      <inertia
        ixx="0.005883"
        ixy="-0.000078"
        ixz="-0.000384"
        iyy="0.006054"
        iyz="-0.000631"
        izz="0.001155" />
    </inertial>
    <visual>
      <origin
        xyz="0 0 0"
        rpy="-1.57 0 0" />
      <geometry>
        <mesh
          filename="../meshes_dae/RF_thigh.dae" scale="1.0 1.0 1.0" />
      </geometry>
      <material
        name="">
        <color
          rgba="0.752941176470588 0.752941176470588 0.752941176470588 1" />
      </material>
    </visual>
    <collision>
      <origin
        xyz="0 0 0"
        rpy="0 0 0" />
      <geometry>
        <mesh
          filename="../meshes_dae/RF_thigh.dae" scale="1.0 1.0 1.0" />
        <!-- <box size="0.01 0.01 0.01"/> -->
      </geometry>
    </collision>
  </link>
  <joint
    name="RF_HFE"
    type="revolute">
    <origin
      xyz="0 -0.077 0"
      rpy="0 0 0" />
    <parent
      link="RF_hip" />
    <child
      link="RF_thigh" />
    <axis
      xyz="0 1 0" />
    <limit
      lower="0"
      upper="1.57"
      effort="20"
      velocity="45" />
  </joint>
  <link
    name="RF_calf">
    <inertial>
      <origin
        xyz="0.0032267 0.0018108 -0.10497"
        rpy="0 0 0" />
      <mass
        value="0.251969" />
      <inertia
        ixx="0.002086"
        ixy="0.000000"
        ixz="0.000002"
        iyy="0.002097"
        iyz="0.000045"
        izz="0.000036" />
    </inertial>
    <visual>
      <origin
        xyz="0 0 0"
        rpy="-1.57 0 0" />
      <geometry>
        <mesh
          filename="../meshes_dae/RF_calf.dae" scale="1.0 1.0 1.0" />
      </geometry>
      <material
        name="">
        <color
          rgba="0.752941176470588 0.752941176470588 0.752941176470588 1" />
      </material>
    </visual>
    <collision>
      <origin
        xyz="0 0 0"
        rpy="0 0 0" />
      <geometry>
        <mesh
          filename="../meshes_dae/RF_calf.dae" scale="1.0 1.0 1.0" />
      </geometry>
    </collision>
  </link>
  <joint
    name="RF_KFE"
    type="revolute">
    <origin
      xyz="0 0 -0.21"
      rpy="0 0 0" />
    <parent
      link="RF_thigh" />
    <child
      link="RF_calf" />
    <axis
      xyz="0 1 0" />
    <limit
      lower="-2.7"
      upper="-1.14"
      effort="20"
      velocity="45" />
  </joint>
  <link
    name="RF_FOOT">
    <inertial>
      <origin
        xyz="0.0019997 0.0051994 0.007454"
        rpy="0 0 0" />
      <mass
        value="0.089225" />
      <inertia
        ixx="0.000027"
        ixy="0.000000"
        ixz="-0.000003"
        iyy="0.000027"
        iyz="-0.000001"
        izz="0.000015" />
    </inertial>
    <visual>
      <origin
        xyz="0 0 0"
        rpy="-1.57 0 0" />
      <geometry>
        <mesh
          filename="../meshes_dae/RF_FOOT.dae" scale="1.0 1.0 1.0" />
      </geometry>
      <material
        name="">
        <color
          rgba="0.486274509803922 0.486274509803922 0.486274509803922 1" />
      </material>
    </visual>
    <collision>
      <origin
        xyz="0 0 0"
        rpy="0 0 0" />
      <geometry>
        <!-- <mesh
          filename="../meshes_dae/RF_FOOT.dae" scale="1.0 1.0 1.0" /> -->
        <sphere radius="0.02"/>
      </geometry>
    </collision>
  </link>
  <joint
    name="RF_foot_fixed"
    type="fixed">
    <origin
      xyz="0 0 -0.21"
      rpy="0 0 0" />
    <parent
      link="RF_calf" />
    <child
      link="RF_FOOT" />
    <axis
      xyz="0 0 0" />
  </joint>
  <link
    name="Spine">
    <inertial>
      <origin
        xyz="0.0071126 -3.1819E-05 -0.0033033"
        rpy="0 0 0" />
      <mass
        value="1.063830" />
      <inertia
        ixx="0.001086"
        ixy="0.000000"
        ixz="-0.000026"
        iyy="0.001221"
        iyz="0.000000"
        izz="0.001543" />
    </inertial>
    <visual>
      <origin
        xyz="0 0 0"
        rpy="-1.57 0 0" />
      <geometry>
        <mesh
          filename="../meshes_dae/Spine.dae" scale="1.0 1.0 1.0" />
      </geometry>
      <material
        name="">
        <color
          rgba="0.752941176470588 0.752941176470588 0.752941176470588 1" />
      </material>
    </visual>
    <collision>
      <origin
        xyz="0 0 0"
        rpy="0 0 0" />
      <geometry>
        <!-- <mesh
          filename="../meshes_dae/Spine.dae" scale="1.0 1.0 1.0" /> -->
        <box size="0.01 0.01 0.01"/>
      </geometry>
    </collision>
  </link>
  <joint
    name="spine_roll"
    type="revolute">
    <origin
      xyz="-0.15 0 0"
      rpy="0 0 0" />
    <parent
      link="base" />
    <child
      link="Spine" />
    <axis
      xyz="1 0 0" />
    <limit
      lower="-1"
      upper="1"
      effort="20"
      velocity="45" />
  </joint>
  <link
    name="base_hind">
    <inertial>
      <origin
        xyz="-0.127890 -0.00064148 0.010896"
        rpy="0 0 0" />
      <mass
        value="3.538370" />
      <inertia
        ixx="0.014945"
        ixy="0.000005"
        ixz="-0.000833"
        iyy="0.012808"
        iyz="-0.000022"
        izz="0.017159" />
    </inertial>
    <visual>
      <origin
        xyz="0 0 0"
        rpy="-1.57 0 0" />
      <geometry>
        <mesh
          filename="../meshes_dae/base_hind.dae" scale="1.0 1.0 1.0" />
        <!-- <box size="0.01 0.01 0.01"/> -->
      </geometry>
      <material
        name="">
        <color
          rgba="0.752941176470588 0.752941176470588 0.752941176470588 1" />
      </material>
    </visual>
    <collision>
      <origin
        xyz="-0.1 0 0"
        rpy="0 0 0" />
      <geometry>
        <!-- <mesh
          filename="../meshes_dae/base_hind.dae" scale="1.0 1.0 1.0" /> -->
        <box size="0.01 0.01 0.01"/>
      </geometry>
    </collision>
  </link>
  <joint
    name="spine_yaw"
    type="revolute">
    <origin
      xyz="0 0 0"
      rpy="0 0 0" />
    <parent
      link="Spine" />
    <child
      link="base_hind" />
    <axis
      xyz="0 0 1" />
    <limit
      lower="-1"
      upper="1"
      effort="20"
      velocity="45" />
  </joint>
  <link
    name="LH_hip">
    <inertial>
      <origin
        xyz="0.0033566 0.00035428 9.8499E-05"
        rpy="0 0 0" />
      <mass
        value="0.605136" />
      <inertia
        ixx="0.000376"
        ixy="0.000003"
        ixz="0.000000"
        iyy="0.000726"
        iyz="0.000001"
        izz="0.000446" />
    </inertial>
    <visual>
      <origin
        xyz="0 0 0"
        rpy="-1.57 0 0" />
      <geometry>
        <mesh
          filename="../meshes_dae/LH_hip.dae" scale="1.0 1.0 1.0" />
      </geometry>
      <material
        name="">
        <color
          rgba="0.752941176470588 0.752941176470588 0.752941176470588 1" />
      </material>
    </visual>
    <collision>
      <origin
        xyz="0 0 0"
        rpy="0 0 0" />
      <geometry>
        <mesh
          filename="../meshes_dae/LH_hip.dae" scale="1.0 1.0 1.0" />
        <!-- <box size="0.01 0.01 0.01"/> -->
      </geometry>
    </collision>
  </link>
  <joint
    name="LH_HAA"
    type="revolute">
    <origin
      xyz="-0.24505 0.06 0"
      rpy="0 0 0" />
    <parent
      link="base_hind" />
    <child
      link="LH_hip" />
    <axis
      xyz="1 0 0" />
    <limit
      lower="-1"
      upper="1"
      effort="20"
      velocity="45" />
  </joint>
  <link
    name="LH_thigh">
    <inertial>
      <origin
        xyz="-0.0035577 -0.016764 -0.030534"
        rpy="0 0 0" />
      <mass
        value="1.178539" />
      <inertia
        ixx="0.005883"
        ixy="0.000078"
        ixz="-0.000384"
        iyy="0.006054"
        iyz="0.000631"
        izz="0.001155" />
    </inertial>
    <visual>
      <origin
        xyz="0 0 0"
        rpy="-1.57 0 0" />
      <geometry>
        <mesh
          filename="../meshes_dae/LH_thigh.dae" scale="1.0 1.0 1.0" />
      </geometry>
      <material
        name="">
        <color
          rgba="0.752941176470588 0.752941176470588 0.752941176470588 1" />
      </material>
    </visual>
    <collision>
      <origin
        xyz="0 0 0"
        rpy="0 0 0" />
      <geometry>
        <mesh
          filename="../meshes_dae/LH_thigh.dae" scale="1.0 1.0 1.0" />
        <!-- <box size="0.01 0.01 0.01"/> -->
      </geometry>
    </collision>
  </link>
  <joint
    name="LH_HFE"
    type="revolute">
    <origin
      xyz="0 0.077 0"
      rpy="0 0 0" />
    <parent
      link="LH_hip" />
    <child
      link="LH_thigh" />
    <axis
      xyz="0 1 0" />
    <limit
      lower="0"
      upper="1.57"
      effort="20"
      velocity="45" />
  </joint>
  <link
    name="LH_calf">
    <inertial>
      <origin
        xyz="0.0032267 0.0018108 -0.10497"
        rpy="0 0 0" />
      <mass
        value="0.251969" />
      <inertia
        ixx="0.002086"
        ixy="0.000000"
        ixz="0.000002"
        iyy="0.002097"
        iyz="0.000045"
        izz="0.000036" />
    </inertial>
    <visual>
      <origin
        xyz="0 0 0"
        rpy="-1.57 0 0" />
      <geometry>
        <mesh
          filename="../meshes_dae/LH_calf.dae" scale="1.0 1.0 1.0" />
      </geometry>
      <material
        name="">
        <color
          rgba="0.752941176470588 0.752941176470588 0.752941176470588 1" />
      </material>
    </visual>
    <collision>
      <origin
        xyz="0 0 0"
        rpy="0 0 0" />
      <geometry>
        <mesh
          filename="../meshes_dae/LH_calf.dae" scale="1.0 1.0 1.0" />
      </geometry>
    </collision>
  </link>
  <joint
    name="LH_KFE"
    type="revolute">
    <origin
      xyz="0 0 -0.21"
      rpy="0 0 0" />
    <parent
      link="LH_thigh" />
    <child
      link="LH_calf" />
    <axis
      xyz="0 1 0" />
    <limit
      lower="-2.7"
      upper="-1.14"
      effort="20"
      velocity="45" />
  </joint>
  <link
    name="LH_FOOT">
    <inertial>
      <origin
        xyz="0.0019997 0.0051994 0.007454"
        rpy="0 0 0" />
      <mass
        value="0.089225" />
      <inertia
        ixx="0.000027"
        ixy="0.000000"
        ixz="-0.000003"
        iyy="0.000027"
        iyz="-0.000001"
        izz="0.000015" />
    </inertial>
    <visual>
      <origin
        xyz="0 0 0"
        rpy="-1.57 0 0" />
      <geometry>
        <mesh
          filename="../meshes_dae/LH_FOOT.dae" scale="1.0 1.0 1.0" />
      </geometry>
      <material
        name="">
        <color
          rgba="0.486274509803922 0.486274509803922 0.486274509803922 1" />
      </material>
    </visual>
    <collision>
      <origin
        xyz="0 0 0"
        rpy="0 0 0" />
      <geometry>
        <!-- <mesh
          filename="../meshes_dae/LH_FOOT.dae" scale="1.0 1.0 1.0" /> -->
        <sphere radius="0.02"/>
      </geometry>
    </collision>
  </link>
  <joint
    name="LH_foot_fixed"
    type="fixed">
    <origin
      xyz="0 0 -0.21"
      rpy="0 0 0" />
    <parent
      link="LH_calf" />
    <child
      link="LH_FOOT" />
    <axis
      xyz="0 0 0" />
  </joint>
  <link
    name="RH_hip">
    <inertial>
      <origin
        xyz="0.0033566 -0.00035428 -9.8499E-05"
        rpy="0 0 0" />
      <mass
        value="0.605136" />
      <inertia
        ixx="0.000376"
        ixy="-0.000003"
        ixz="0.000000"
        iyy="0.000726"
        iyz="0.000001"
        izz="0.000446" />
    </inertial>
    <visual>
      <origin
        xyz="0 0 0"
        rpy="-1.57 0 0" />
      <geometry>
        <mesh
          filename="../meshes_dae/RH_hip.dae" scale="1.0 1.0 1.0" />
      </geometry>
      <material
        name="">
        <color
          rgba="0.752941176470588 0.752941176470588 0.752941176470588 1" />
      </material>
    </visual>
    <collision>
      <origin
        xyz="0 0 0"
        rpy="0 0 0" />
      <geometry>
        <mesh
          filename="../meshes_dae/RH_hip.dae" scale="1.0 1.0 1.0" />
        <!-- <box size="0.01 0.01 0.01"/> -->
      </geometry>
    </collision>
  </link>
  <joint
    name="RH_HAA"
    type="revolute">
    <origin
      xyz="-0.24505 -0.06 0"
      rpy="0 0 0" />
    <parent
      link="base_hind" />
    <child
      link="RH_hip" />
    <axis
      xyz="1 0 0" />
    <limit
      lower="-1"
      upper="1"
      effort="20"
      velocity="45" />
  </joint>
  <link
    name="RH_thigh">
    <inertial>
      <origin
        xyz="-0.0035577 0.016764 -0.030534"
        rpy="0 0 0" />
      <mass
        value="1.178539" />
      <inertia
        ixx="0.005883"
        ixy="-0.000078"
        ixz="-0.000384"
        iyy="0.006054"
        iyz="-0.000631"
        izz="0.001155" />
    </inertial>
    <visual>
      <origin
        xyz="0 0 0"
        rpy="-1.57 0 0" />
      <geometry>
        <mesh
          filename="../meshes_dae/RH_thigh.dae" scale="1.0 1.0 1.0" />
      </geometry>
      <material
        name="">
        <color
          rgba="0.752941176470588 0.752941176470588 0.752941176470588 1" />
      </material>
    </visual>
    <collision>
      <origin
        xyz="0 0 0"
        rpy="0 0 0" />
      <geometry>
        <mesh
          filename="../meshes_dae/RH_thigh.dae" scale="1.0 1.0 1.0" />
        <!-- <box size="0.01 0.01 0.01"/> -->
      </geometry>
    </collision>
  </link>
  <joint
    name="RH_HFE"
    type="revolute">
    <origin
      xyz="0 -0.077 0"
      rpy="0 0 0" />
    <parent
      link="RH_hip" />
    <child
      link="RH_thigh" />
    <axis
      xyz="0 1 0" />
    <limit
      lower="0"
      upper="1.57"
      effort="20"
      velocity="45" />
  </joint>
  <link
    name="RH_calf">
    <inertial>
      <origin
        xyz="0.0032267 0.0018108 -0.10497"
        rpy="0 0 0" />
      <mass
        value="0.251969" />
      <inertia
        ixx="0.002086"
        ixy="0.000000"
        ixz="0.000002"
        iyy="0.002097"
        iyz="0.000045"
        izz="0.000036" />
    </inertial>
    <visual>
      <origin
        xyz="0 0 0"
        rpy="-1.57 0 0" />
      <geometry>
        <mesh
          filename="../meshes_dae/RH_calf.dae" scale="1.0 1.0 1.0" />
      </geometry>
      <material
        name="">
        <color
          rgba="0.752941176470588 0.752941176470588 0.752941176470588 1" />
      </material>
    </visual>
    <collision>
      <origin
        xyz="0 0 0"
        rpy="0 0 0" />
      <geometry>
        <mesh
          filename="../meshes_dae/RH_calf.dae" scale="1.0 1.0 1.0" />
      </geometry>
    </collision>
  </link>
  <joint
    name="RH_KFE"
    type="revolute">
    <origin
      xyz="0 0 -0.21"
      rpy="0 0 0" />
    <parent
      link="RH_thigh" />
    <child
      link="RH_calf" />
    <axis
      xyz="0 1 0" />
    <limit
      lower="-2.7"
      upper="-1.14"
      effort="20"
      velocity="45" />
  </joint>
  <link
    name="RH_FOOT">
    <inertial>
      <origin
        xyz="0.0019997 0.0051994 0.007454"
        rpy="0 0 0" />
      <mass
        value="0.089225" />
      <inertia
        ixx="0.000027"
        ixy="0.000000"
        ixz="-0.000003"
        iyy="0.000027"
        iyz="-0.000001"
        izz="0.000015" />
    </inertial>
    <visual>
      <origin
        xyz="0 0 0"
        rpy="-1.57 0 0" />
      <geometry>
        <mesh
          filename="../meshes_dae/RH_FOOT.dae" scale="1.0 1.0 1.0" />
      </geometry>
      <material
        name="">
        <color
          rgba="0.486274509803922 0.486274509803922 0.486274509803922 1" />
      </material>
    </visual>
    <collision>
      <origin
        xyz="0 0 0"
        rpy="0 0 0" />
      <geometry>
        <!-- <mesh
          filename="../meshes_dae/RH_FOOT.dae" scale="1.0 1.0 1.0" /> -->
        <sphere radius="0.02"/>
      </geometry>
    </collision>
  </link>
  <joint
    name="RH_foot_fixed"
    type="fixed">
    <origin
      xyz="0 0 -0.21"
      rpy="0 0 0" />
    <parent
      link="RH_calf" />
    <child
      link="RH_FOOT" />
    <axis
      xyz="0 0 0" />
  </joint>
</robot>